Workbook
Name cATEGORIA_RISCHIO: 'Appoggio (2)'!$G$3:$G$8
Name CATEGORIA1: 'Appoggio (2)'!$G$3:$G$8
Name CATEGORIE: 'Appoggio (2)'!$G$3:$G$8
Name CATEGORIE: Appoggio!$G$3:$G$8
Name CATEGORIE1: 'Appoggio (2)'!$G$3:$G$8
Name Informativa_e_reporting: 'Appoggio (2)'!$R$54:$R$56
Name Informativa_e_reporting: Appoggio!$R$54:$R$56
Name Informativa_e_reporting1: 'Appoggio (2)'!$Z$14:$Z$16
Name Rischio_Clinico_Sanitario: 'Appoggio (2)'!$Q$3:$Q$16
Name Rischio_Clinico_Sanitario: Appoggio!$Q$3:$Q$16
Name Rischio_Clinico_Sanitario1: 'Appoggio (2)'!$U$3:$U$16
Name Rischio_di_Compliance: 'Appoggio (2)'!$Q$46:$Q$51
Name Rischio_di_Compliance: Appoggio!$Q$46:$Q$51
Name Rischio_di_Compliance1: 'Appoggio (2)'!$AA$3:$AA$8
Name Rischio_Esterno: 'Appoggio (2)'!$Q$17:$Q$22
Name Rischio_Esterno: Appoggio!$Q$17:$Q$22
Name Rischio_Esterno1: 'Appoggio (2)'!$V$3:$V$8
Name Rischio_Finanziario: 'Appoggio (2)'!$Q$23:$Q$27
Name Rischio_Finanziario: Appoggio!$Q$23:$Q$27
Name Rischio_Finanziario1: 'Appoggio (2)'!$W$3:$W$7
Name Rischio_Operativo: 'Appoggio (2)'!$Q$34:$Q$45
Name Rischio_Operativo: Appoggio!$Q$34:$Q$45
Name Rischio_Operativo1: 'Appoggio (2)'!$Y$3:$Y$28
Name Rischio_Strategico: 'Appoggio (2)'!$Q$28:$Q$33
Name Rischio_Strategico: Appoggio!$Q$28:$Q$33
Name Rischio_Strategico1: 'Appoggio (2)'!$X$3:$X$8
Name Salute_sicurezza_e_ambiente: 'Appoggio (2)'!$R$57:$R$68
Name Salute_sicurezza_e_ambiente: Appoggio!$R$57:$R$68
Name Salute_sicurezza_e_ambiente1: 'Appoggio (2)'!$Z$17:$Z$28
Name SANITARIO: 'Appoggio (2)'!$Q$3:$Q$16
Name SANITARIO: Appoggio!$Q$3:$Q$16

Sheet Copertina
A12: RISK ASSESSMENT ASST Della Brianza
A14: Registro dei Rischi
A16: Risk Guide
A18: Risk Model
A20: Metriche di Valutazione
A23: TABELLA RISCHIO SECONDO MODELLO HERM (MO 3330)
A24: QD_ENT_20265_3330
A25: rev 0 del 20/05/2026

Sheet Registro dei Rischi
C2: Registro dei Rischi
C5: OWNERSHIP DEL RISCHIO | H5: ANAGRAFICA DEL RISCHIO | L5: ANALISI DEL RISCHIO | N5: VALUTAZIONE RISCHIO INERENTE | X5: VALUTAZIONE SISTEMA DI CONTROLLI IN ESSERE | AN5: VALUTAZIONE RISCHIO RESIDUO | AT5: VALUTAZIONE RISCHIO RESIDUO | AW5: AZIONI | AX5: VALUTAZIONE AZIONI DI MITIGAZIONE E MIGLIORAMENTO | BB5: VALUTAZIONE RISCHIO RESIDUO TO-BE
C6: # Rischio | D6: ID Rischio | E6: Direzione | F6: Risk Owner | G6: Processo | H6: Categoria Rischio Livello 1 | I6: Categoria Rischio Livello 2 | J6: Categoria Rischio Livello 3 | K6: Scenario di rischio | L6: Principali cause del rischio | M6: Principali conseguenze del rischio | N6: Driver di valutazione del rischio | O6: Economico-Finanziario | P6: Reputazionale | Q6: Salute e Sicurezza | R6: Compliance | S6: Gestionale - Operativo | T6: Ambiente | U6: Impatto Inerente | V6: Probabilità Inerente | W6: RPN Inerente | X6: Mitigazioni operative CORRETTIVE in essere | Y6: Valutazione controlli su impatto eco-fin | Z6: Valutazione controlli su impatto reputazionale | AA6: Valutazione controlli su impatto salute e sicurezza | AB6: Valutazione controlli su impatto compliance | AC6: Valutazione controlli su impatto gest-ope | AD6: Valutazione controlli su impatto ambientale | AE6: Fattore riduzione impatto eco-fin | AF6: Fattore riduzione impatto reputazionale | AG6: Fattore riduzione impatto salute e sicurezza | AH6: Fattore riduzione impatto compliance | AI6: Fattore riduzione impatto gest-ope | AJ6: Fattore riduzione impatto ambientale | AK6: Mitigazioni operative PREVENTIVE in essere | AL6: Valutazione controlli preventivi | AM6: Fattore riduzione probabilità | AN6: Economico-Finanziario | AO6: Reputazionale | AP6: Salute e Sicurezza | AQ6: Compliance | AR6: Gestionale- Operativo | AS6: Ambiente | AT6: Impatto Residuo | AU6: Probabilità Residua | AV6: RPN Residuo | AW6: Azioni di mitigazione e miglioramento | AX6: Efficacia delle azioni CORRETTIVE | AY6: Fattore riduzione impatto | AZ6: Efficacia delle azioni PREVENTIVE | BA6: Fattore riduzione probabilità | BB6: Impatto Residuo to-be | BC6: Probabilità residua to-be | BD6: RPN Residuo to-be
C7: 1 | D7: =_xlfn.CONCAT(VLOOKUP(G7,Appoggio!B:E,4,0),"_",VLOOKUP(H7,Appoggio!G:H,2,0),"_",C7) -> #NAME? | G7: PAC | K7: Processi: Persone: Fattori esterni: Strumenti: | L7: Processi: Persone: Fattori esterni: Strumenti: | M7: Economiche: - Danno d'immagine: Compliance Normativa: - Salute e sicurezza: - Gestionale - Operativo: - | U7: =IF(AND(O7="N.A.",P7="N.A.",Q7="N.A.",R7="N.A.",S7="N.A.",T7="N.A."),"N.A.",MAX(O7:T7)) -> 0 | W7: =IF(OR(U7="N.A.",V7="N.A."),"N.A.",U7*V7) -> 0 | AE7: =IF(Y7="","",VLOOKUP(Y7,Appoggio!$M$3:$N$7,2,0)) | AF7: =IF(Z7="","",VLOOKUP(Z7,Appoggio!$M$3:$N$7,2,0)) | AG7: =IF(AA7="","",VLOOKUP(AA7,Appoggio!$M$3:$N$7,2,0)) | AH7: =IF(AB7="","",VLOOKUP(AB7,Appoggio!$M$3:$N$7,2,0)) | AI7: =IF(AC7="","",VLOOKUP(AC7,Appoggio!$M$3:$N$7,2,0)) | AJ7: =IF(AD7="","",VLOOKUP(AD7,Appoggio!$M$3:$N$7,2,0)) | AL7: 0 | AM7: =IF(AL7="","",VLOOKUP(AL7,Appoggio!$M$3:$N$7,2,0)) -> 1 | AN7: =IF(AND(O7="", AE7=""), "", IF(AE7="", O7, IF(O7="", "", O7 * AE7))) | AO7: =IF(AND(P7="", AF7=""), "", IF(AF7="", P7, IF(P7="", "", P7 * AF7))) | AP7: =IF(AND(Q7="", AG7=""), "", IF(AG7="", Q7, IF(Q7="", "", Q7 * AG7))) | AQ7: =IF(AND(R7="", AH7=""), "", IF(AH7="", R7, IF(R7="", "", R7 * AH7))) | AR7: =IF(AND(S7="", AI7=""), "", IF(AI7="", S7, IF(S7="", "", S7 * AI7))) | AS7: =IF(AND(T7="", AJ7=""), "", IF(AJ7="", T7, IF(T7="", "", T7 * AJ7))) | AT7: =MAX(AN7:AS7) -> 0 | AU7: =IF(ISBLANK(AL7), V7, AM7 * V7) -> 0 | AV7: =AT7*AU7 -> 0 | AY7: =IF(AX7="","",VLOOKUP(AX7,Appoggio!$M$3:$N$7,2,0)) | BA7: =IF(AZ7="","",VLOOKUP(AZ7,Appoggio!$M$3:$N$7,2,0)) | BB7: =IF(AY7="",AT7,AT7*AY7) -> 0 | BC7: =IF(BA7="",AU7,AU7*BA7) -> 0 | BD7: =BB7*BC7 -> 0
C8: 2 | D8: =_xlfn.CONCAT(VLOOKUP(G8,Appoggio!B:E,4,0),"_",VLOOKUP(H8,Appoggio!G:H,2,0),"_",C8) -> #NAME? | G8: PAC | L8: Processi: Persone: Fattori esterni: - Strumenti: | M8: Economiche: - Danno d'immagine: Compliance Normativa: - Salute e sicurezza: - Gestionale - Operativo: - | U8: =IF(AND(O8="N.A.",P8="N.A.",Q8="N.A.",R8="N.A.",S8="N.A.",T8="N.A."),"N.A.",MAX(O8:T8)) -> 0 | W8: =IF(OR(U8="N.A.",V8="N.A."),"N.A.",U8*V8) -> 0 | AE8: =IF(Y8="","",VLOOKUP(Y8,Appoggio!$M$3:$N$7,2,0)) | AF8: =IF(Z8="","",VLOOKUP(Z8,Appoggio!$M$3:$N$7,2,0)) | AG8: =IF(AA8="","",VLOOKUP(AA8,Appoggio!$M$3:$N$7,2,0)) | AH8: =IF(AB8="","",VLOOKUP(AB8,Appoggio!$M$3:$N$7,2,0)) | AI8: =IF(AC8="","",VLOOKUP(AC8,Appoggio!$M$3:$N$7,2,0)) | AJ8: =IF(AD8="","",VLOOKUP(AD8,Appoggio!$M$3:$N$7,2,0)) | AL8: 0 | AM8: =IF(AL8="","",VLOOKUP(AL8,Appoggio!$M$3:$N$7,2,0)) -> 1 | AN8: =IF(AND(O8="", AE8=""), "", IF(AE8="", O8, IF(O8="", "", O8 * AE8))) | AO8: =IF(AND(P8="", AF8=""), "", IF(AF8="", P8, IF(P8="", "", P8 * AF8))) | AP8: =IF(AND(Q8="", AG8=""), "", IF(AG8="", Q8, IF(Q8="", "", Q8 * AG8))) | AQ8: =IF(AND(R8="", AH8=""), "", IF(AH8="", R8, IF(R8="", "", R8 * AH8))) | AR8: =IF(AND(S8="", AI8=""), "", IF(AI8="", S8, IF(S8="", "", S8 * AI8))) | AS8: =IF(AND(T8="", AJ8=""), "", IF(AJ8="", T8, IF(T8="", "", T8 * AJ8))) | AT8: =MAX(AN8:AS8) -> 0 | AU8: =IF(ISBLANK(AL8), V8, AM8 * V8) -> 0 | AV8: =AT8*AU8 -> 0 | AY8: =IF(AX8="","",VLOOKUP(AX8,Appoggio!$M$3:$N$7,2,0)) | BA8: =IF(AZ8="","",VLOOKUP(AZ8,Appoggio!$M$3:$N$7,2,0)) | BB8: =IF(AY8="",AT8,AT8*AY8) -> 0 | BC8: =IF(BA8="",AU8,AU8*BA8) -> 0 | BD8: =BB8*BC8 -> 0
C9: 3 | D9: =_xlfn.CONCAT(VLOOKUP(G9,Appoggio!B:E,4,0),"_",VLOOKUP(H9,Appoggio!G:H,2,0),"_",C9) -> #NAME? | G9: PAC | L9: Processi: Persone: Fattori esterni: - Strumenti: | M9: Economiche: Danno d'immagine: Compliance Normativa: Salute e Sicurezza: - Gestionale - Operativo: - | U9: =IF(AND(O9="N.A.",P9="N.A.",Q9="N.A.",R9="N.A.",S9="N.A.",T9="N.A."),"N.A.",MAX(O9:T9)) -> 0 | W9: =IF(OR(U9="N.A.",V9="N.A."),"N.A.",U9*V9) -> 0 | AE9: =IF(Y9="","",VLOOKUP(Y9,Appoggio!$M$3:$N$7,2,0)) | AF9: =IF(Z9="","",VLOOKUP(Z9,Appoggio!$M$3:$N$7,2,0)) | AG9: =IF(AA9="","",VLOOKUP(AA9,Appoggio!$M$3:$N$7,2,0)) | AH9: =IF(AB9="","",VLOOKUP(AB9,Appoggio!$M$3:$N$7,2,0)) | AI9: =IF(AC9="","",VLOOKUP(AC9,Appoggio!$M$3:$N$7,2,0)) | AJ9: =IF(AD9="","",VLOOKUP(AD9,Appoggio!$M$3:$N$7,2,0)) | AL9: 0 | AM9: =IF(AL9="","",VLOOKUP(AL9,Appoggio!$M$3:$N$7,2,0)) -> 1 | AN9: =IF(AND(O9="", AE9=""), "", IF(AE9="", O9, IF(O9="", "", O9 * AE9))) | AO9: =IF(AND(P9="", AF9=""), "", IF(AF9="", P9, IF(P9="", "", P9 * AF9))) | AP9: =IF(AND(Q9="", AG9=""), "", IF(AG9="", Q9, IF(Q9="", "", Q9 * AG9))) | AQ9: =IF(AND(R9="", AH9=""), "", IF(AH9="", R9, IF(R9="", "", R9 * AH9))) | AR9: =IF(AND(S9="", AI9=""), "", IF(AI9="", S9, IF(S9="", "", S9 * AI9))) | AS9: =IF(AND(T9="", AJ9=""), "", IF(AJ9="", T9, IF(T9="", "", T9 * AJ9))) | AT9: =MAX(AN9:AS9) -> 0 | AU9: =IF(ISBLANK(AL9), V9, AM9 * V9) -> 0 | AV9: =AT9*AU9 -> 0 | AY9: =IF(AX9="","",VLOOKUP(AX9,Appoggio!$M$3:$N$7,2,0)) | BA9: =IF(AZ9="","",VLOOKUP(AZ9,Appoggio!$M$3:$N$7,2,0)) | BB9: =IF(AY9="",AT9,AT9*AY9) -> 0 | BC9: =IF(BA9="",AU9,AU9*BA9) -> 0 | BD9: =BB9*BC9 -> 0
C10: 4 | D10: =_xlfn.CONCAT(VLOOKUP(G10,Appoggio!B:E,4,0),"_",VLOOKUP(H10,Appoggio!G:H,2,0),"_",C10) -> #NAME? | G10: PAC | L10: Processi: Persone: Fattori esterni: Strumenti: | M10: Economiche: - Danno d'immagine: - Compliance Normativa: Salute e Sicurezza: - Gestionale - Operativo: | U10: =IF(AND(O10="N.A.",P10="N.A.",Q10="N.A.",R10="N.A.",S10="N.A.",T10="N.A."),"N.A.",MAX(O10:T10)) -> 0 | W10: =IF(OR(U10="N.A.",V10="N.A."),"N.A.",U10*V10) -> 0 | AE10: =IF(Y10="","",VLOOKUP(Y10,Appoggio!$M$3:$N$7,2,0)) | AF10: =IF(Z10="","",VLOOKUP(Z10,Appoggio!$M$3:$N$7,2,0)) | AG10: =IF(AA10="","",VLOOKUP(AA10,Appoggio!$M$3:$N$7,2,0)) | AH10: =IF(AB10="","",VLOOKUP(AB10,Appoggio!$M$3:$N$7,2,0)) | AI10: =IF(AC10="","",VLOOKUP(AC10,Appoggio!$M$3:$N$7,2,0)) | AJ10: =IF(AD10="","",VLOOKUP(AD10,Appoggio!$M$3:$N$7,2,0)) | AL10: 0 | AM10: =IF(AL10="","",VLOOKUP(AL10,Appoggio!$M$3:$N$7,2,0)) -> 1 | AN10: =IF(AND(O10="", AE10=""), "", IF(AE10="", O10, IF(O10="", "", O10 * AE10))) | AO10: =IF(AND(P10="", AF10=""), "", IF(AF10="", P10, IF(P10="", "", P10 * AF10))) | AP10: =IF(AND(Q10="", AG10=""), "", IF(AG10="", Q10, IF(Q10="", "", Q10 * AG10))) | AQ10: =IF(AND(R10="", AH10=""), "", IF(AH10="", R10, IF(R10="", "", R10 * AH10))) | AR10: =IF(AND(S10="", AI10=""), "", IF(AI10="", S10, IF(S10="", "", S10 * AI10))) | AS10: =IF(AND(T10="", AJ10=""), "", IF(AJ10="", T10, IF(T10="", "", T10 * AJ10))) | AT10: =MAX(AN10:AS10) -> 0 | AU10: =IF(ISBLANK(AL10), V10, AM10 * V10) -> 0 | AV10: =AT10*AU10 -> 0 | AY10: =IF(AX10="","",VLOOKUP(AX10,Appoggio!$M$3:$N$7,2,0)) | BA10: =IF(AZ10="","",VLOOKUP(AZ10,Appoggio!$M$3:$N$7,2,0)) | BB10: =IF(AY10="",AT10,AT10*AY10) -> 0 | BC10: =IF(BA10="",AU10,AU10*BA10) -> 0 | BD10: =BB10*BC10 -> 0
C11: 5C11:M13C11:M12C11:L12C11:N12K7C11:M11C11:P13C11:S13K7C11:AA13 | D11: =_xlfn.CONCAT(VLOOKUP(G11,Appoggio!B:E,4,0),"_",VLOOKUP(H11,Appoggio!G:H,2,0),"_",C11) -> #NAME? | G11: PAC | L11: Processi: - inefficacia del processo di comunicazione intra-dipartimentale - inadeguatezza dell'allocazione di ruoli e responsabilità - assenza/inadeguata verifica ed approvazione dei contenuti da parte del responsabile di struttura/direzione Persone: invio volontaria/involontaria dei contenuti anche in assenza di approvazione Fattori esterni: - Strumenti: - | M11: Economiche: - Danno d'immagine: Reputazione danneggiata Compliance Normativa: - Salute e sicurezza: - Gestionale - Operativo: -operatizioni di correzione e rettifica | U11: =IF(AND(O11="N.A.",P11="N.A.",Q11="N.A.",R11="N.A.",S11="N.A.",T11="N.A."),"N.A.",MAX(O11:T11)) -> 0 | W11: =IF(OR(U11="N.A.",V11="N.A."),"N.A.",U11*V11) -> 0 | AE11: =IF(Y11="","",VLOOKUP(Y11,Appoggio!$M$3:$N$7,2,0)) | AF11: =IF(Z11="","",VLOOKUP(Z11,Appoggio!$M$3:$N$7,2,0)) | AG11: =IF(AA11="","",VLOOKUP(AA11,Appoggio!$M$3:$N$7,2,0)) | AH11: =IF(AB11="","",VLOOKUP(AB11,Appoggio!$M$3:$N$7,2,0)) | AI11: =IF(AC11="","",VLOOKUP(AC11,Appoggio!$M$3:$N$7,2,0)) | AJ11: =IF(AD11="","",VLOOKUP(AD11,Appoggio!$M$3:$N$7,2,0)) | AL11: 0 | AM11: =IF(AL11="","",VLOOKUP(AL11,Appoggio!$M$3:$N$7,2,0)) -> 1 | AN11: =IF(AND(O11="", AE11=""), "", IF(AE11="", O11, IF(O11="", "", O11 * AE11))) | AO11: =IF(AND(P11="", AF11=""), "", IF(AF11="", P11, IF(P11="", "", P11 * AF11))) | AP11: =IF(AND(Q11="", AG11=""), "", IF(AG11="", Q11, IF(Q11="", "", Q11 * AG11))) | AQ11: =IF(AND(R11="", AH11=""), "", IF(AH11="", R11, IF(R11="", "", R11 * AH11))) | AR11: =IF(AND(S11="", AI11=""), "", IF(AI11="", S11, IF(S11="", "", S11 * AI11))) | AS11: =IF(AND(T11="", AJ11=""), "", IF(AJ11="", T11, IF(T11="", "", T11 * AJ11))) | AT11: =MAX(AN11:AS11) -> 0 | AU11: =IF(ISBLANK(AL11), V11, AM11 * V11) -> 0 | AV11: =AT11*AU11 -> 0 | AY11: =IF(AX11="","",VLOOKUP(AX11,Appoggio!$M$3:$N$7,2,0)) | BA11: =IF(AZ11="","",VLOOKUP(AZ11,Appoggio!$M$3:$N$7,2,0)) | BB11: =IF(AY11="",AT11,AT11*AY11) -> 0 | BC11: =IF(BA11="",AU11,AU11*BA11) -> 0 | BD11: =BB11*BC11 -> 0
C12: 6 | D12: =_xlfn.CONCAT(VLOOKUP(G12,Appoggio!B:E,4,0),"_",VLOOKUP(H12,Appoggio!G:H,2,0),"_",C12) -> #NAME? | G12: PAC | L12: Processi: - assenza di informazioni sull'ubicazione dell'Ufficio URP Persone: - Fattori esterni: - Strumenti: -collocazione locali non facilmente identificabiili ed accesibili | M12: Economiche: Danno d'immagine: - Reputazione danneggiata Compliance normativa: mancata aderenza alla normativa che istituisce l'URP Salute e Sicurezza: lesioni al personale interno all'URP Gestionale - Operativo: | U12: =IF(AND(O12="N.A.",P12="N.A.",Q12="N.A.",R12="N.A.",S12="N.A.",T12="N.A."),"N.A.",MAX(O12:T12)) -> 0 | W12: =IF(OR(U12="N.A.",V12="N.A."),"N.A.",U12*V12) -> 0 | AE12: =IF(Y12="","",VLOOKUP(Y12,Appoggio!$M$3:$N$7,2,0)) | AF12: =IF(Z12="","",VLOOKUP(Z12,Appoggio!$M$3:$N$7,2,0)) | AG12: =IF(AA12="","",VLOOKUP(AA12,Appoggio!$M$3:$N$7,2,0)) | AH12: =IF(AB12="","",VLOOKUP(AB12,Appoggio!$M$3:$N$7,2,0)) | AI12: =IF(AC12="","",VLOOKUP(AC12,Appoggio!$M$3:$N$7,2,0)) | AJ12: =IF(AD12="","",VLOOKUP(AD12,Appoggio!$M$3:$N$7,2,0)) | AL12: 0 | AM12: =IF(AL12="","",VLOOKUP(AL12,Appoggio!$M$3:$N$7,2,0)) -> 1 | AN12: =IF(AND(O12="", AE12=""), "", IF(AE12="", O12, IF(O12="", "", O12 * AE12))) | AO12: =IF(AND(P12="", AF12=""), "", IF(AF12="", P12, IF(P12="", "", P12 * AF12))) | AP12: =IF(AND(Q12="", AG12=""), "", IF(AG12="", Q12, IF(Q12="", "", Q12 * AG12))) | AQ12: =IF(AND(R12="", AH12=""), "", IF(AH12="", R12, IF(R12="", "", R12 * AH12))) | AR12: =IF(AND(S12="", AI12=""), "", IF(AI12="", S12, IF(S12="", "", S12 * AI12))) | AS12: =IF(AND(T12="", AJ12=""), "", IF(AJ12="", T12, IF(T12="", "", T12 * AJ12))) | AT12: =MAX(AN12:AS12) -> 0 | AU12: =IF(ISBLANK(AL12), V12, AM12 * V12) -> 0 | AV12: =AT12*AU12 -> 0 | AY12: =IF(AX12="","",VLOOKUP(AX12,Appoggio!$M$3:$N$7,2,0)) | BA12: =IF(AZ12="","",VLOOKUP(AZ12,Appoggio!$M$3:$N$7,2,0)) | BB12: =IF(AY12="",AT12,AT12*AY12) -> 0 | BC12: =IF(BA12="",AU12,AU12*BA12) -> 0 | BD12: =BB12*BC12 -> 0
C13: 7 | D13: =_xlfn.CONCAT(VLOOKUP(G13,Appoggio!B:E,4,0),"_",VLOOKUP(H13,Appoggio!G:H,2,0),"_",C13) -> #NAME? | G13: PAC | K13: Aggressione verbale e/o fisica verso gli operatori da parte dell'utenza | L13: Processi: Persone: - personale non adeguatamente formato - dimenticanze e disattenzione verso il paziente - inefficace attività di comunicazione da parte degli operatori - carenza personale di vigilanza Fattori esterni: - pregiudizio dell'utenza '- spazio non adeguato Strumenti: - insufficienti barriere di protezione a tutela dell'operatore - strutture locali (assenza vie di fuga e sistemi allerta) allocazione locali | M13: Economiche: - possibili danni ad attrezzature ed arredi '- extra costi Danno d'immagine: Compliance Normativa: Salute e Sicurezza: - infortunio - stress lavoro correlato Gestionale - Operativo: - ritardi/sospensione nell'attività lavorativa | U13: =IF(AND(O13="N.A.",P13="N.A.",Q13="N.A.",R13="N.A.",S13="N.A.",T13="N.A."),"N.A.",MAX(O13:T13)) -> 0 | W13: =IF(OR(U13="N.A.",V13="N.A."),"N.A.",U13*V13) -> 0 | AE13: =IF(Y13="","",VLOOKUP(Y13,Appoggio!$M$3:$N$7,2,0)) | AF13: =IF(Z13="","",VLOOKUP(Z13,Appoggio!$M$3:$N$7,2,0)) | AG13: =IF(AA13="","",VLOOKUP(AA13,Appoggio!$M$3:$N$7,2,0)) | AH13: =IF(AB13="","",VLOOKUP(AB13,Appoggio!$M$3:$N$7,2,0)) | AI13: =IF(AC13="","",VLOOKUP(AC13,Appoggio!$M$3:$N$7,2,0)) | AJ13: =IF(AD13="","",VLOOKUP(AD13,Appoggio!$M$3:$N$7,2,0)) | AL13: 0 | AM13: =IF(AL13="","",VLOOKUP(AL13,Appoggio!$M$3:$N$7,2,0)) -> 1 | AN13: =IF(AND(O13="", AE13=""), "", IF(AE13="", O13, IF(O13="", "", O13 * AE13))) | AO13: =IF(AND(P13="", AF13=""), "", IF(AF13="", P13, IF(P13="", "", P13 * AF13))) | AP13: =IF(AND(Q13="", AG13=""), "", IF(AG13="", Q13, IF(Q13="", "", Q13 * AG13))) | AQ13: =IF(AND(R13="", AH13=""), "", IF(AH13="", R13, IF(R13="", "", R13 * AH13))) | AR13: =IF(AND(S13="", AI13=""), "", IF(AI13="", S13, IF(S13="", "", S13 * AI13))) | AS13: =IF(AND(T13="", AJ13=""), "", IF(AJ13="", T13, IF(T13="", "", T13 * AJ13))) | AT13: =MAX(AN13:AS13) -> 0 | AU13: =IF(ISBLANK(AL13), V13, AM13 * V13) -> 0 | AV13: =AT13*AU13 -> 0 | AY13: =IF(AX13="","",VLOOKUP(AX13,Appoggio!$M$3:$N$7,2,0)) | BA13: =IF(AZ13="","",VLOOKUP(AZ13,Appoggio!$M$3:$N$7,2,0)) | BB13: =IF(AY13="",AT13,AT13*AY13) -> 0 | BC13: =IF(BA13="",AU13,AU13*BA13) -> 0 | BD13: =BB13*BC13 -> 0
C14: 8 | D14: =_xlfn.CONCAT(VLOOKUP(G14,Appoggio!B:E,4,0),"_",VLOOKUP(H14,Appoggio!G:H,2,0),"_",C14) -> #NAME? | G14: PAC | K14: Errori nell'attività di protocollazione | L14: Processi: - errata/inefficace trattamento dei documenti in uscita con finalità giuridico-probatorie - assenza/inefficacia del processo di gestione e trattamento dei documenti in uscita - inefficienza del processo di controllo della codifica corretta del documento - inefficacia del processo di verifica della corretta conservazione del documento nell'albo pretorio Persone: - errore nell'assegnazione del protocollo - errore umano Fattori esterni: - Strumenti: - inaffidabilità dei supporti informatici - blocco dei sistemi IT | M14: Economiche: - perdita di uno strumento di prevenzione del contenzioso; extra costo per spese di giudizio Danno d'immagine: - Reputazione danneggiata Compliance Normativa: non ottemperanza ad obblighi di natura normativa Salute e Sicurezza: - Gestionale - Operativo: - - ritardi sull'operatività aziendale; sovraccarico di lavoro | U14: =IF(AND(O14="N.A.",P14="N.A.",Q14="N.A.",R14="N.A.",S14="N.A.",T14="N.A."),"N.A.",MAX(O14:T14)) -> 0 | W14: =IF(OR(U14="N.A.",V14="N.A."),"N.A.",U14*V14) -> 0 | AE14: =IF(Y14="","",VLOOKUP(Y14,Appoggio!$M$3:$N$7,2,0)) | AF14: =IF(Z14="","",VLOOKUP(Z14,Appoggio!$M$3:$N$7,2,0)) | AG14: =IF(AA14="","",VLOOKUP(AA14,Appoggio!$M$3:$N$7,2,0)) | AH14: =IF(AB14="","",VLOOKUP(AB14,Appoggio!$M$3:$N$7,2,0)) | AI14: =IF(AC14="","",VLOOKUP(AC14,Appoggio!$M$3:$N$7,2,0)) | AJ14: =IF(AD14="","",VLOOKUP(AD14,Appoggio!$M$3:$N$7,2,0)) | AL14: 0 | AM14: =IF(AL14="","",VLOOKUP(AL14,Appoggio!$M$3:$N$7,2,0)) -> 1 | AN14: =IF(AND(O14="", AE14=""), "", IF(AE14="", O14, IF(O14="", "", O14 * AE14))) | AO14: =IF(AND(P14="", AF14=""), "", IF(AF14="", P14, IF(P14="", "", P14 * AF14))) | AP14: =IF(AND(Q14="", AG14=""), "", IF(AG14="", Q14, IF(Q14="", "", Q14 * AG14))) | AQ14: =IF(AND(R14="", AH14=""), "", IF(AH14="", R14, IF(R14="", "", R14 * AH14))) | AR14: =IF(AND(S14="", AI14=""), "", IF(AI14="", S14, IF(S14="", "", S14 * AI14))) | AS14: =IF(AND(T14="", AJ14=""), "", IF(AJ14="", T14, IF(T14="", "", T14 * AJ14))) | AT14: =MAX(AN14:AS14) -> 0 | AU14: =IF(ISBLANK(AL14), V14, AM14 * V14) -> 0 | AV14: =AT14*AU14 -> 0 | AY14: =IF(AX14="","",VLOOKUP(AX14,Appoggio!$M$3:$N$7,2,0)) | BA14: =IF(AZ14="","",VLOOKUP(AZ14,Appoggio!$M$3:$N$7,2,0)) | BB14: =IF(AY14="",AT14,AT14*AY14) -> 0 | BC14: =IF(BA14="",AU14,AU14*BA14) -> 0 | BD14: =BB14*BC14 -> 0

Sheet Risk Guide
C2: Risk Guide
C6: # Rischio | D6: Numero progressivo associato a ciascuno scenario di rischio
C8: ID Rischio | D8: Codice univoco associato a ciascuno scenario di rischio rilevato, contenente la sigla del Processo, la Categoria di Rischio e il numero progressivo associato a ciascuno scenario di rischio
C10: Direzione | D10: Area aziendale responsabile della gestione del rischio identificato
C12: Risk Owner | D12: Responsabile dell'Area aziendale che gestisce il rischio, ne comprende l’entità, decide la misura di trattamento (tollerarlo, mitigarlo, esternalizzarlo, eliminarlo) e guida la sua implementazione
C14: Processo | D14: Processo di riferimento, individuato sulla base del Process Model specifico per la struttura
C16: Categoria Rischio Liv. 1 | D16: Raggruppamento dei rischi secondo categorie omogenee per natura, caratteristiche o manifestazione. Le categorie sono identificate e definite nel Risk Model.
C18: Categoria Rischio Liv. 2 | D18: Sotto-categorie di rischio identificate nel Risk Model
C20: Categoria Rischio Liv. 2 | D20: Categoria di rischio di 3° livello identificate nel Risk Model
C22: Scenario di rischio | D22: Descrizione del rischio rilevato. Rischio: Evento probabile ma non certo che può portare ad uno scostamento (negativo) dagli obiettivi o dal valore atteso
C24: Principali cause del rischio | D24: Principali cause che possono scatenare il rischio rilevato
C26: Principali conseguenze del rischio | D26: Principali conseguenze che possono derivare dal rischio
C28: Valutazione del Rischio | D28: Informazioni a supporto del processo di valutazione
... C40: Valutazione Rischio Residuo to-be | D40: Valore del rischio residuo previsto, considerata l'implementazione delle azioni di mitigazione e miglioramento

Sheet Risk Model
C2: Risk Model
C5: Categoria di Rischio Liv. 1 | D5: Categoria di Rischio Liv. 2 | E5: Descrizione | F5: Categoria di Rischio Liv. 3 | G5: Descrizione
C6: CLINICO-SANITARI (Rischi derivanti da eventi che possono prolungare il periodo di degenza, il peggioramento delle condizioni di salute o la morte del paziente) | D6: Anestesiologico | E6: Durante l’induzione dell’anestesia o in fase di rianimazione, somministrazione di farmaci/dosaggi sbagliati o esecuzione di procedure/manovre errate che possono causare reazioni avverse (es. lesioni, reazioni allergiche).
D7: Assistenziale | E7: Ogni inesattezza, incompletezza od omissione commessa nell’esecuzione di procedure/manovre clinico-assistenziali mediche e infermieristiche (es. posizionamento catetere/drenaggio, preparazione intervento, mobilizzazione e posizionamento nel posto letto, sorveglianza post-operatoria) che possono causare aventi avversi.
D8: Atti di autolesione e tentativi di suicidio | E8: Possibilità del paziente di provocarsi dolore o lesioni superficiali intenzionali finalizzati all’autolesionismo o alla morte. Atti di autolesione non intenzionali.
D9: Caduta | E9: Improvviso, non intenzionale, inaspettato spostamento verso il basso dalla posizione ortostatica o assisa o clinostatica del paziente, ospite o caregiver. La testimonianza delle cadute è basata sul ricordo del paziente e/o la descrizione della caduta da parte dei testimoni. Qui sono incluse i pazienti che dormendo sulla sedia cadono per terra, i pazienti ritrovati sul pavimento e le cadute avvenute nonostante il supporto.
D10: Chirurgico | E10: Corpi estranei nel focolaio chirurgico, intervento su parte o lato del corpo sbagliata, esecuzione chirurgica impropria, chirurgia non necessaria, utilizzo di materiale chirurgico difettoso, gestione non corretta del paziente chirurgico.
D11: Diagnostico | E11: Esami o procedure diagnostiche non eseguite, programmate ma non eseguite, eseguite in modo inadeguato o scorretto o con materiali inadeguati, eseguite tardivamente, non appropriate. L’area include le procedure invasive e non invasive a scopo diagnostico.
D12: Gestione / redazione documenti | E12: Inesattezza, incompletezza, scarsa leggibilità, incomprensione degli acronimi/abbreviazioni della documentazione utilizzata nei processi clinico-assistenziali (es. consenso informato, cartella clinica, cartella infermieristica, referti, lettera dimissioni). Documentazione sanitaria che non rappresenta esaustivamente il percorso del paziente (inclusi eventuali trasferimenti) o che non contiene informazioni per garantire la continuità delle cure.
D13: Identificazione del paziente | E13: Possibilità di scambiare dati anagrafici di pazienti diversi oppure di eseguire procedure diagnostico-terapeutiche su un paziente ma prescritte a pazienti diversi.
D14: Infezione correlata all'assistenza | E14: Possibilità di acquisire infezioni in ogni ambito assistenziale, incluso gli ospedali per acuti, il day-hospital/day-surgery, le strutture di lungodegenza, gli ambulatori, l’assistenza domiciliare, le strutture residenziali territoriali.
D15: Ostetrico e neonatale, inclusi i trigger | E15: Ogni inesattezza, incompletezza od omissione che può verificarsi nelle fasi di gestione dei percorsi di cura materno-neonatali nelle fasi di gravidanza, parto e puerperio.
D16: Prevenzione | E16: Ogni inesattezza, incompletezza od omissione che può verificarsi nelle campagne di promozione della salute individuale e collettiva (es. screening, iniziative di sensibilizzazione) o nelle attività finalizzate alla riduzione dei fattori di rischio delle malattie (es. vaccini, profilassi antibiotica).
D17: Sperimentazioni cliniche | E17: Violazione dei diritti, della sicurezza e del benessere dei soggetti coinvolti nelle sperimentazioni cliniche. Inesattezza/incompletezza del protocollo di sperimentazione. Mancata indipendenza del Comitato Etico.
D18: Terapeutico | E18: Ogni evento avverso, indesiderabile, non intenzionale, prevenibile che può causare o portare ad un uso inappropriato del farmaco o ad un pericolo per il paziente: errore di prescrizione, di trasmissione della prescrizione, etichettatura, confezionamento o denominazione, allestimento, dispensazione, distribuzione, somministrazione, educazione, monitoraggio ed uso.
D19: Trasfusionale | E19: Ogni inesattezza, incompletezza od omissione che può verificarsi nelle fasi del processo trasfusionale: prelievo del campione, richiesta di emocomponenti, accettazione-registrazione-assegnazione presso il Servizio Trasfusionale e trasfusione presso la struttura sanitaria.
C20: ESTERNI (Rischi derivanti da eventi e cambiamenti nell'ambiente e nel contesto in cui l'azienda opera) | D20: Contesto socio-economico nazionale e regionale | E20: Dinamiche macroeconomiche o di contesto socio-politico che generano ripercussioni negative sullo scenario in cui l’Azienda opera.
D21: Eventi naturali o accidentale | E21: Eventi catastrofali o calamitosi di tipo naturale (es. alluvioni, inondazioni, terremoti) o atto involontario che genera conseguenze negative sull’operatività aziendale.
D22: Evoluzione del contesto normativo | E22: Variazioni/cambiamenti sfavorevoli delle norme/regolamenti regionali e nazionali vigenti con ripercussioni sulle attività e sulla struttura organizzativa.
D23: Gestione Terze Parti | E23: Difformità qualitative, ritardi nei tempi di fornitura e ogni altro tipo di inadempimento contrattuale generato dai fornitori di beni e servizi. Informazioni inesatte, ritardi e ogni altra forma di scarsa collaborazione di soggetti coinvolti nei progetti di partnership.
D24: Illeciti esterni | E24: Atto/comportamento illecito doloso o colposo commesso da terzi o che coinvolgono terze parti che causa un danno all’azienda, alle persone o alle cose ad esclusione degli attacchi informatici.
D25: Sicurezza informatica | E25: Attacchi informatici posti in essere da individui o organizzazioni criminali finalizzati a trafugare, disabilitare o distruggere dati o generare guasti e interruzioni ai sistemi informatici aziendali.
C26: FINANZIARI (Rischi legati agli aspetti finanziari, ad esempio mercato, credito) | D26: Contabilità e reporting finanziario | E26: Inesattezze, errori ed omissioni commessi nelle attività e nei processi di rilevazione contabile e predisposizione della reportistica direzionale (es. controllo di gestione) che compromettono l’attendibilità dei dati aziendali.
D27: Erariale patrimoniale | E27: Ogni circostanza di danneggiamento o perdita di beni o denaro generato alle finanze pubbliche da comportamenti o omissioni dolose o colpose commessi da soggetti legati all’amministrazione da un rapporto di servizio.
D28: Fiscale | E28: Inesattezze, errori ed omissioni commessi nell’esecuzione delle attività e nella gestione dei processi della fiscalità aziendale.
D29: Liquidità e credito | E29: Eccessi o carenze delle disponibilità di cassa rispetto alla pianificazione dei flussi di cassa. Riduzione del valore dei crediti iscritti in bilancio causato da inadempimenti contrattuali o abbassamento del grado di solvibilità dei debitori.
D30: Tassi d’interesse | E30: Variazioni inattese dei tassi d'interesse con ricadute sui valori iscritti tra le attività e passività di bilancio e/o sulla gestione finanziaria.
C31: STRATEGICI (Rischi derivanti da decisioni strategiche sbagliate, dalla loro attuazione inadeguata o da una governance aziendale non adeguata al raggiungimento degli obiettivi aziendali. I rischi strategici possono anche derivare dal disallineamento della strategia con la visione, la missione e i valori fondamentali dell'azienda). | D31: Comunicazione e relazioni istituzionali | E31: Ogni evento/circostanza che compromette la capacità dell’Azienda di comunicare efficacemente con stakeholder esterni e/o creare/mantenere relazioni.
D32: Governance | E32: Possibilità di incoerenza fra obiettivi strategici e mission vision aziendali. Struttura organizzativa (ruoli e responsabilità) e linee guida/principi di governo parziali o inadeguati.
D33: Immagine/Reputazione | E33: Ogni evento/circostanza che compromette l'immagine dell’Azienda davanti gli stakeholders interni o esterni rilevanti (es. dipendenti, associazioni pazienti, enti di volontariato, fornitori, autorità e istituzioni nazionali/internazionali) derivante dalla diffusione di notizie negative su media, stampa, web o altri mezzi di comunicazione.
D34: Investimenti e patrimonio | E34: Inadeguata gestione degli investimenti o del patrimonio. Inappropriate o inadeguate Iniziative di crescita organica, azioni di miglioramento o progetti di ampliamento del sistema di offerta.
D35: Pianificazione strategica | E35: Pianificazione strategica non rispondente alle priorità del sistema socio sanitario regionale o incompatibile con le risorse disponibili. Obiettivi definiti sulla base di dati/informazioni parziali, incompleti o inadeguati.
D36: Sistema di Controllo Interno | E36: Inadeguato / inefficace processo di identificazione, valutazione, gestione e monitoraggio dei rischi e/o inadeguatezza dei presidi di controllo implementati.
C37: OPERATIVI (Rischi derivanti da inadeguatezze o errori nei processi aziendali e di supporto e/o difetti nel sistema dei controlli operativi) | D37: Attività, processi e procedure | E37: Carenze nel disegno dei processi dell’Azienda, inadempienze / negligenze / errori nelle modalità di esecuzione / gestione delle attività operative e dai relativi presidi di controllo.
D38: Asset infrastrutturali e tecnologia | E38: Infrastrutture e tecnologie, diverse dalle apparecchiature sanitarie, strutturalmente inadatte (es. rete informatica che non consente di caricare i documenti sanitari, sede operativa che non garantisce la regolazione della temperatura nei locali di cura) o oggetto di malfunzionamenti (es. blocco server), danneggiamenti, errori d’uso, carente manutenzione.
D39: Business Continuity | E39: Compromissione dell'integrità e della continuità operativa di persone, asset infrastrutturali e/o tecnologici aziendali per un evento non direttamente collegato all’attività dell’Azienda.
D40: Comunicazione e relazioni | E40: Criticità o mancanza di trasparenza nelle modalità di comunicazione degli operatori con i pazienti, caregiver o familiari, prima, durante e dopo l’esecuzione dei servizi sanitari. Mancata o inadeguata comunicazione interna tra operatori e i criticità relative all'accesso alle informazioni e alle comunicazioni tra management e operatori sanitari.
D41: Continuità e coordinamento percorsi assistenziali | E41: Carenze nella definizione dei percorsi assistenziali e nelle attività di presa in carico dei bisogni assistenziali. Inefficaci o incompleti meccanismi di coordinamento tra operatori sanitari che possono pregiudicare la continuità delle cure e la qualità dell’assistenza.
D42: Edifici e spazi comuni | E42: Ogni fatto o circostanza che arreca danni a persone o cose in vari ambiti (es. ascensore, scale, corridoi, parcheggi, spazi esterni alle strutture sanitarie).
D43: Gestione apparecchiature sanitarie | E43: Malfunzionamenti dovuto a problemi tecnici di fabbricazione (non causati dall’utilizzatore), malfunzionamenti dovuto all’utilizzatore (manutenzione, impostazione, altri errori d’uso), uso in condizioni non appropriate, manutenzione inadeguata, istruzioni inadeguate, pulizia non corretta, utilizzo oltre i limiti di durata previsti delle apparecchiature sanitarie.
...

Sheet Metriche di valutazione
C2: Metriche di valutazione
C5: IMPATTO
C6: SCALA | D6: VALUTAZIONE | E6: DESCRIZIONE | F6: Immagine e reputazione | G6: Compliance normativa | H6: Ambiente | I6: Salute e sicurezza | J6: Gestionale - Operativo
C7: 10 | D7: Catastrofico | E7: L'impatto sugli obiettivi aziendali e sulla gestione comporta una significativa ed estesa revisione delle strategie con un coinvolgimento straordinario di amministratori e del top management | F7: - Reputazione danneggiata a livello nazionale e/o internazionale - Reputazione danneggiata non risolvibile temporalmente - Notizie sui media nazionali e/o internazionali con esposizione mediatica di lungo periodo | G7: - Non ottemperanza di rilevante entità ad obblighi di natura contrattuale/normativa con restrizioni rilevanti per l’azienda (es. commissariamento o sanzioni interdittive che incidono sulla continuità aziendale) - Commissione di un reato che prevede la reclusione superiore a 2 anni | H7: - Impatto con significativi danni ambientali gravi e persistenti all'esterno del sito - Superamenti ingenti e sistematici di norme o limiti prescrittivi | I7: Personale/popolazione: - Infortunio mortale multiplo - Malattia professionale di più persone - Incidente che ha causato invalidità permanente/morte di una o più persone esterne al sito Pazienti: - L'evento comporta il decesso di uno o più pazienti | J7: - Impatto sugli obiettivi aziendali - Gestione richiede coinvolgimento straordinario del top management, degli amministratori ed un utilizzo straordinario di risorse aggiuntive - Gestione comporta una significativa ed estesa revisione delle strategie - Non risolvibile entro l’anno
C8: 7 | D8: Rilevante | E8: L'impatto sugli obiettivi aziendali e sulla gestione comporta una contenuta e mirata revisione delle strategie con un coinvolgimento mirato di amministratori e del top management | F8: - Reputazione danneggiata a livello nazionale e/o internazionale - Reputazione danneggiata risolvibile in massimo 1 mese - Notizie sui media nazionali e/o internazionali con esposizione mediatica di medio periodo | G8: - Non ottemperanza di significativa entità ad obblighi di natura contrattuale / normativa con restrizioni significative dell'operatività per l’azienda - Sanzioni amministrative / penali / pecuniarie di significativa entità - Commissione di un reato che prevede la reclusione fino a 2 anni | H8: - L'impatto ambientale investe ampie aree interne al sito e aree esterne - Superamenti quantitativamente importanti e ripetuti di norme o limiti prescrittivi | I8: Personale/popolazione: - Un infortunio con invalidità permanente / un morto - Un incidente che ha causato lesioni fisiche alla popolazione esterna al sito Pazienti: - L'evento comporta l'invalidità permanente o il rischio di morte (es. shock, arresto cardiaco) | J8: - Impatto sugli obiettivi aziendali - Gestione richiede un coinvolgimento notevole del top management, degli amministratori ed un utilizzo massivo di risorse aggiuntive - Gestione comporta una revisione mirata delle strategie - Risolvibile entro l’anno
C9: 5 | D9: Significativo | E9: L'impatto sugli obiettivi aziendali e sulla gestione richiede un coinvolgimento del top management significativo per essere risolto | F9: - Reputazione danneggiata a livello nazionale - Reputazione danneggiata risolvibile in massimo 15 giorni - Notizie sui media nazionali con esposizione mediatica di breve periodo | G9: - Non ottemperanza di media entità ad obblighi di natura contrattuale/normativa - Sanzioni amministrative / penali / pecuniarie di modesta entità | H9: - L'impatto ambientale investe, oltre ad aree interne al sito, anche aree esterne circostanti - Superamenti multipli di norme o limiti prescrittivi | I9: Personale/popolazione: - 1 o più infortuni con prognosi superiore a 40 giorni Pazienti: - L'evento comporta una invalidità temporanea; prolungamento della degenza > 1 mese | J9: - Impatto sugli obiettivi aziendali - Gestione richiede un coinvolgimento del top management ed utilizzo di risorse aggiuntive - Risolvibile in un mese
C10: 3 | D10: Contenuto | E10: L'impatto sugli obiettivi aziendali e sulla gestione richiede un impegno del top management per minimizzarlo | F10: - Reputazione danneggiata a livello nazionale - Reputazione danneggiata risolvibile in massimo 7 giorni - Notizie spot su media nazionali | G10: - Non ottemperanza di modesta entità ad obblighi di natura contrattuale/normativa - Sanzioni amministrative / penali / pecuniarie di moderata entità | H10: - L'impatto ambientale investe trasversalmente il sito nel suo complesso pur rimanendo su area localizzata - Singolo superamento di norme o limiti prescrittivi | I10: Personale/popolazione: - 1 o più infortuni con prognosi inferiore a 40 giorni Pazienti: - L'evento comporta un danno temporaneo; prolungamento della degenza < 1 mese | J10: - Impatto sugli obiettivi aziendali - Gestione richiede limitato impegno del top management e limitato utilizzo di risorse - Risolvibile in una settimana
C11: 2 | D11: Trascurabile | E11: L'impatto sugli obiettivi aziendali e sulla gestione può essere assorbito attraverso la normale attività | F11: - Reputazione danneggiata a livello locale/regionale - Reputazione danneggiata risolvibile in massimo 3 giorni - Notizie spot su media locali | G11: - Non ottemperanza di lieve entità ad obblighi di natura contrattuale/normativa - Sanzioni amministrative / penali / pecuniarie di trascurabile entità | H11: - Impatto ambientale temporaneo circoscritto a spazi o aree specifiche interne al sito in area non sensibile - Nessun superamento di norme o limiti prescrittivi | I11: Personale/popolazione: - Lievi infortuni nel corso dello svolgimento delle attività quotidiane Pazienti: - L'evento non comporta danni di rilievo; rende necessario un maggior monitoraggio | J11: - Impatto sugli obiettivi aziendali - Gestione assorbita attraverso la normale attività, senza l’utilizzo di ulteriori risorse - Risolvibile in giornata
C13: IMPATTO ECONOMICO
C14: SCALA | D14: VALUTAZIONE | E14: CLUSTER A | F14: CLUSTER B | G14: CLUSTER C
B15: ASST | C15: 2 | D15: Trascurabile | E15: •< 0,02% ricavi totali | F15: •< 0,015% ricavi totali | G15: •< 0,01% ricavi totali
C16: 3 | D16: Contenuto | E16: •0,02-0,25% ricavi totali | F16: •0,015-0,18% ricavi totali | G16: •0,01-0,13% ricavi totali
C17: 5 | D17: Significativo | E17: •0,25-2,5% ricavi totali | F17: •0,18-1,8% ricavi totali | G17: •0,13-1,3% ricavi totali
C18: 7 | D18: Rilevante | E18: •2,5-5% ricavi totali | F18: •1,8-3,6% ricavi totali | G18: •1,3-2,6% ricavi totali
C19: 10 | D19: Estremo | E19: •>5% ricavi totali | F19: •>3,6% ricavi totali | G19: •>2,6% ricavi totali
B20: ATS | C20: 2 | D20: Trascurabile | E20: •< 0,02% ricavi totali | F20: •<0,01% ricavi totali | G20: •<0,01% ricavi totali
C21: 3 | D21: Contenuto | E21: •0,02-0,3% ricavi totali | F21: •0,01-0,2% ricavi totali | G21: •0,01-0,15% ricavi totali
C22: 5 | D22: Significativo | E22: •0,3-3,5% ricavi totali | F22: •0,2-2% ricavi totali | G22: •0,15-1% ricavi totali
C23: 7 | D23: Rilevante | E23: •3,5-7% ricavi totali | F23: •2-4% ricavi totali | G23: •1-2% ricavi totali
C24: 10 | D24: Estremo | E24: •>7% ricavi totali | F24: •>4% ricavi totali | G24: •>2% ricavi totali
B25: IRCCS | C25: 2 | D25: Trascurabile | E25: •< 0,03% ricavi totali | F25: •< 0,02% ricavi totali | G25: •< 0,01% ricavi totali
C26: 3 | D26: Contenuto | E26: •0,03-0,2% ricavi totali | F26: •0,02-0,18% ricavi totali | G26: •0,01-0,1% ricavi totali
C27: 5 | D27: Significativo | E27: •0,2-2% ricavi totali | F27: •0,18-1,5% ricavi totali | G27: •0,1-1,2% ricavi totali
C28: 7 | D28: Rilevante | E28: •2-4% ricavi totali | F28: •1,5-3% ricavi totali | G28: •1,2-2,4% ricavi totali
C29: 10 | D29: Estremo | E29: •>4% ricavi totali | F29: •>3% ricavi totali | G29: •>2,4% ricavi totali
C31: PROBABILITA' | G31: CONTROLLI
C32: INDICE DI PROBABILITA' | D32: VALUTAZIONE | E32: PROBABILITA' DELL'EVENTO | G32: SCALA | H32: Fattore di riduzione | I32: VALUTAZIONE
C33: 6 | D33: Molto probabile | E33: - Probabilità ≥ 50% - Evento atteso almeno una volta all'anno - Evento quasi certo - Si prevede che l’evento possa verificarsi nel breve termine - L'evento si è verificato negli ultimi mesi | G33: 4 | H33: 0.1 | I33: Controllo che opera nel suo complesso in modo efficace ed efficiente assicurando il monitoraggio e il contenimento dei rischi
C34: 5 | D34: Probabile | E34: - Probabilità compresa fra il 25% ≤ x ≤ 50% - Evento atteso una volta ogni 2/3 anni - Evento molto verosimile - Si prevede che l’evento possa verificarsi nel breve / medio termine - L'evento si è verificato negli ultimi 12 mesi | G34: 3 | H34: 0.25 | I34: Controllo che opera nel suo complesso in modo efficace ed efficiente ma che presenta circosritte carenze con lieve esposizione al rischio
C35: 4 | D35: Moderatamente probabile | E35: - Probabilità 10% ≤ x ≤ 25% - Evento atteso una volta ogni 4/10 anni - Evento verosimile - Si prevede che l’evento possa verificarsi nel medio termine - L'evento si è verificato negli ultimi 3 anni | G35: 2 | H35: 0.5 | I35: Controllo con carenze localizzate con esposizione lieve al rischio o per il quale è in essere un intervento correttivo / di mitigazione in fase di conclusione (es. procedura in corso di approvazione)
C36: 3 | D36: Poco probabile | E36: - Probabilità 5% ≤ x ≤ 10% - Evento atteso una volta ogni 10/20 anni - Evento poco verosimile - Si prevede che l’evento possa verificarsi nel medio/lungo termine - L'evento si è verificato negli ultimi 5 anni | G36: 1 | H36: 0.75 | I36: Controllo che presenta significative carenze e con esposizione elevata al rischio
C37: 2 | D37: Improbabile | E37: - Probabilità ≤ 5% - Evento atteso una volta ogni 20 anni o di più - Evento molto poco verosimile - Si prevede che l'evento possa verificarsi nel lungo termine - L'evento non si è mai verificato nel passato o si è verificato una sola volta negli ultimi 10 anni | G37: 0 | H37: 1 | I37: Assenza totale di elementi di controllo, o che presenta gravi criticità, con una esposizione alta al rischio

Sheet Appoggio
B2: Processo | C2: Ruolo | D2: Risk Owner | E2: Pocesso/Short | G2: Categoria Rischio | H2: Short | J2: Impatto | K2: Probabilità | M2: Valutazione Controllo | N2: Fattore di riduzione | P2: Categoria Rischio Liv. 1 | Q2: Categoria Rischio Liv. 2 | R2: Categoria Rischio Liv. 3 | S2: Short
B3: Ufficio Relazioni con il Pubblico | E3: URP | G3: Rischio Clinico Sanitario | H3: SANIT | J3: N.A. | K3: N.A. | M3: 4 | N3: 0.1 | P3: Rischio Clinico_Sanitario | Q3: Anestesiologico | R3: N.A. | S3: SANIT
B4: Bilancio e Rendicontazione | E4: BIL | G4: Rischio Esterno | H4: EST | J4: 2 | K4: 2 | M4: 3 | N4: 0.25 | P4: Rischio Clinico_Sanitario | Q4: Assistenziale | R4: N.A. | S4: SANIT
B5: Gestione Acquisti (provveditorato-economato) | E5: ACQ | G5: Rischio Finanziario | H5: FIN | J5: 3 | K5: 3 | M5: 2 | N5: 0.5 | P5: Rischio Clinico_Sanitario | Q5: Atti di autolesione e tentativi di suicidio | R5: N.A. | S5: SANIT
B6: Sistemi Informativi Aziendali | E6: SIA | G6: Rischio Strategico | H6: STR | J6: 5 | K6: 4 | M6: 1 | N6: 0.75 | P6: Rischio Clinico_Sanitario | Q6: Caduta | R6: N.A. | S6: SANIT
B7: Ingegneria Clinica | E7: ING | G7: Rischio Operativo | H7: OPE | J7: 7 | K7: 5 | M7: 0 | N7: 1 | P7: Rischio Clinico_Sanitario | Q7: Chirurgico | R7: N.A. | S7: SANIT
B8: Farmacia | E8: FAR | G8: Rischio di Compliance | H8: COMP | J8: 10 | K8: 6 | P8: Rischio Clinico_Sanitario | Q8: Diagnostico | R8: N.A. | S8: SANIT
B9: Ricerca scientifica e sperimentazioni cliniche | E9: RIC | P9: Rischio Clinico_Sanitario | Q9: Gestione / redazione documenti | R9: N.A. | S9: SANIT
B10: Affari Generali e Legali | E10: AFF.GEN | P10: Rischio Clinico_Sanitario | Q10: Identificazione del paziente | R10: N.A. | S10: SANIT
B11: Gestione delle Risorse Umane | E11: HR | P11: Rischio Clinico_Sanitario | Q11: Infezione correlata all'assistenza | R11: N.A. | S11: SANIT
B12: Ufficio Tecnico Patrimoniale | E12: UFF.TEC | P12: Rischio Clinico_Sanitario | Q12: Ostetrico e neonatale, inclusi i trigger | R12: N.A. | S12: SANIT
B13: Qualità, Risk Management e Internal Auditing | E13: QRM | P13: Rischio Clinico_Sanitario | Q13: Prevenzione | R13: N.A. | S13: SANIT
B14: Sanità pubblica veterinaria | E14: VET | P14: Rischio Clinico_Sanitario | Q14: Sperimentazioni cliniche | R14: N.A. | S14: SANIT
B15: SC Unità di Epidemiologia | E15: EPIDEM | P15: Rischio Clinico_Sanitario | Q15: Terapeutico | R15: N.A. | S15: SANIT
B16: Medicina preventiva di comunità - screening | E16: SCREENING | P16: Rischio Clinico_Sanitario | Q16: Trasfusionale | R16: N.A. | S16: SANIT
B17: Gestione Operativa | E17: GEST.OP | P17: Rischio Esterno | Q17: Contesto socio-economico nazionale e regionale | R17: N.A. | S17: EST
B18: Dipartimento Igiene e Prevenzione Sanitaria | E18: IGIENE | P18: Rischio Esterno | Q18: Eventi naturali o accidentali | R18: N.A. | S18: EST
B19: Controllo di gestione | E19: C.GEST | P19: Rischio Esterno | Q19: Evoluzione del contesto normativo | R19: N.A. | S19: EST
B20: Trasporto STAM/STEN | E20: STAM/STEN | P20: Rischio Esterno | Q20: Gestione Terze Parti | R20: N.A. | S20: EST
... B25: Attività di comunicazione aziendale e relazioni esterne | E25: COMUNIC | P25: Rischio Finanziario | Q25: Fiscale | R25: N.A. | S25: FIN
E26: PAC | P26: Rischio Finanziario | Q26: Liquidità e credito | R26: N.A. | S26: FIN
P27: Rischio Finanziario | Q27: Tassi d’interesse | R27: N.A. | S27: FIN
P28: Rischio Strategico | Q28: Comunicazione e relazioni istituzionali | R28: N.A. | S28: STR
P29: Rischio Strategico | Q29: Governance | R29: N.A. | S29: STR
P30: Rischio Strategico | Q30: Immagine/Reputazione | R30: N.A. | S30: STR
P31: Rischio Strategico | Q31: Investimenti e patrimonio | R31: N.A. | S31: STR
P32: Rischio Strategico | Q32: Pianificazione strategica | R32: N.A. | S32: STR
P33: Rischio Strategico | Q33: Sistema di Controllo Interno | R33: N.A. | S33: STR
P34: Rischio Operativo | Q34: Attività, processi e procedure | R34: N.A. | S34: OPE
P35: Rischio Operativo | Q35: Asset infrastrutturali e tecnologia | R35: N.A. | S35: OPE
P36: Rischio Operativo | Q36: Business Continuity | R36: N.A. | S36: OPE
P37: Rischio Operativo | Q37: Comunicazione e relazioni | R37: N.A. | S37: OPE
P38: Rischio Operativo | Q38: Continuità e coordinamento percorsi assistenziali | R38: N.A. | S38: OPE
... P68: Rischio Operativo | Q68: Salute sicurezza e ambiente | R68: Rischio da videoterminale | S68: OPE

Sheet Appoggio (2)
B2: Processo | C2: Ruolo | D2: Risk Owner | E2: Pocesso/Short | G2: Categoria Rischio | H2: Short | J2: Impatto | K2: Probabilità | M2: Valutazione Controllo | N2: Fattore di riduzione | P2: Categoria Rischio Liv. 1 | Q2: Categoria Rischio Liv. 2 | R2: Categoria Rischio Liv. 3 | S2: Short
B3: Ufficio Relazioni con il Pubblico | E3: URP | G3: Rischio Clinico Sanitario1 | H3: SANIT | J3: N.A. | K3: N.A. | M3: 4 | N3: 0.1 | P3: Rischio Clinico_Sanitario | Q3: Anestesiologico | R3: N.A. | S3: SANIT | U3: Anestesiologico | V3: Contesto socio-economico nazionale e regionale | W3: Contabilità e reporting finanziario | X3: Comunicazione e relazioni istituzionali | Y3: Sistema di Controllo Interno | AA3: Anticorruzione
B4: Bilancio e Rendicontazione | E4: BIL | G4: Rischio Esterno1 | H4: EST | J4: 2 | K4: 2 | M4: 3 | N4: 0.25 | P4: Rischio Clinico_Sanitario | Q4: Assistenziale | R4: N.A. | S4: SANIT | U4: Assistenziale | V4: Eventi naturali o accidentali | W4: Erariale patrimoniale | X4: Governance | Y4: Attività, processi e procedure | AA4: Codice etico
B5: Gestione Acquisti (provveditorato-economato) | E5: ACQ | G5: Rischio Finanziario1 | H5: FIN | J5: 3 | K5: 3 | M5: 2 | N5: 0.5 | P5: Rischio Clinico_Sanitario | Q5: Atti di autolesione e tentativi di suicidio | R5: N.A. | S5: SANIT | U5: Atti di autolesione e tentativi di suicidio | V5: Evoluzione del contesto normativo | W5: Fiscale | X5: Immagine/Reputazione | Y5: Asset infrastrutturali e tecnologia | AA5: Contrattualistica e controversie legali
B6: Sistemi Informativi Aziendali | E6: SIA | G6: Rischio Strategico1 | H6: STR | J6: 5 | K6: 4 | M6: 1 | N6: 0.75 | P6: Rischio Clinico_Sanitario | Q6: Caduta | R6: N.A. | S6: SANIT | U6: Caduta | V6: Gestione Terze Parti | W6: Liquidità e credito | X6: Investimenti e patrimonio | Y6: Business Continuity | AA6: Normativa (regionale, nazionale, comunitaria)
B7: Ingegneria Clinica | E7: ING | G7: Rischio Operativo1 | H7: OPE | J7: 7 | K7: 5 | M7: 0 | N7: 1 | P7: Rischio Clinico_Sanitario | Q7: Chirurgico | R7: N.A. | S7: SANIT | U7: Chirurgico | V7: Illeciti esterni | W7: Tassi d’interesse | X7: Pianificazione strategica | Y7: Comunicazione e relazioni | AA7: Regolamenti interni
B8: Farmacia | E8: FAR | G8: Rischio di Compliance1 | H8: COMP | J8: 10 | K8: 6 | P8: Rischio Clinico_Sanitario | Q8: Diagnostico | R8: N.A. | S8: SANIT | U8: Diagnostico | V8: Sicurezza informatica | X8: Sistema di Controllo Interno | Y8: Continuità e coordinamento percorsi assistenziali | AA8: Sicurezza delle informazioni e tutela privacy
B9: Ricerca scientifica e sperimentazioni cliniche | E9: RIC | P9: Rischio Clinico_Sanitario | Q9: Gestione / redazione documenti | R9: N.A. | S9: SANIT | U9: Gestione / redazione documenti | Y9: Edifici e spazi comuni
B10: Affari Generali e Legali | E10: AFF.GEN | P10: Rischio Clinico_Sanitario | Q10: Identificazione del paziente | R10: N.A. | S10: SANIT | U10: Identificazione del paziente | Y10: Gestione apparecchiature sanitarie
B11: Gestione delle Risorse Umane | E11: HR | P11: Rischio Clinico_Sanitario | Q11: Infezione correlata all'assistenza | R11: N.A. | S11: SANIT | U11: Infezione correlata all'assistenza | Y11: Gestione farmaci e dispositivi medici
B12: Ufficio Tecnico Patrimoniale | E12: UFF.TEC | P12: Rischio Clinico_Sanitario | Q12: Ostetrico e neonatale, inclusi i trigger | R12: N.A. | S12: SANIT | U12: Ostetrico e neonatale, inclusi i trigger | Y12: Illeciti interni
B13: Qualità, Risk Management e Internal Auditing | E13: QRM | P13: Rischio Clinico_Sanitario | Q13: Prevenzione | R13: N.A. | S13: SANIT | U13: Prevenzione | Y13: Persone e cultura
B14: Sanità pubblica veterinaria | E14: VET | P14: Rischio Clinico_Sanitario | Q14: Sperimentazioni cliniche | R14: N.A. | S14: SANIT | U14: Sperimentazioni cliniche | Y14: Informativa e reporting | Z14: Informativa strategica / di programmazione
B15: SC Unità di Epidemiologia | E15: EPIDEM | P15: Rischio Clinico_Sanitario | Q15: Terapeutico | R15: N.A. | S15: SANIT | U15: Terapeutico | Z15: Misurazione delle performance
B16: Medicina preventiva di comunità - screening | E16: SCREENING | P16: Rischio Clinico_Sanitario | Q16: Trasfusionale | R16: N.A. | S16: SANIT | U16: Trasfusionale | Z16: Informativa interna ed esterna
B17: Gestione Operativa | E17: GEST.OP | P17: Rischio Esterno | Q17: Contesto socio-economico nazionale e regionale | R17: N.A. | S17: EST | Y17: Salute sicurezza e ambiente | Z17: Atti di violenza su operatori
B18: Dipartimento Igiene e Prevenzione Sanitaria | E18: IGIENE | P18: Rischio Esterno | Q18: Eventi naturali o accidentali | R18: N.A. | S18: EST | Z18: Rischio biologico
B19: Controllo di gestione | E19: C.GEST | P19: Rischio Esterno | Q19: Evoluzione del contesto normativo | R19: N.A. | S19: EST | Z19: Rischio chimico
B20: Trasporto STAM/STEN | E20: STAM/STEN | P20: Rischio Esterno | Q20: Gestione Terze Parti | R20: N.A. | S20: EST | Z20: Rischio fisico
B21: Gestione parco veicoli | E21: VEICOLI | P21: Rischio Esterno | Q21: Illeciti esterni | R21: N.A. | S21: EST | Z21: Rischio da atmosfera esplosiva
B22: Telemedicina | E22: TELEM | P22: Rischio Esterno | Q22: Sicurezza informatica | R22: N.A. | S22: EST | Z22: Rischio incendio
B23: Fisica Sanitaria | E23: F.SANIT | P23: Rischio Finanziario | Q23: Contabilità e reporting finanziario | R23: N.A. | S23: FIN | Z23: Rischio da infortuni generici
B24: Gestione del servizio prevenzione e protezione | E24: SPP | P24: Rischio Finanziario | Q24: Erariale patrimoniale | R24: N.A. | S24: FIN | Z24: Rischio da movimentazione di carichi e pazienti
B25: Attività di comunicazione aziendale e relazioni esterne | E25: COMUNIC | P25: Rischio Finanziario | Q25: Fiscale | R25: N.A. | S25: FIN | Z25: Rischio radiazioni
E26: PAC | P26: Rischio Finanziario | Q26: Liquidità e credito | R26: N.A. | S26: FIN | Z26: Rischio sociale
P27: Rischio Finanziario | Q27: Tassi d’interesse | R27: N.A. | S27: FIN | Z27: Rischio stress lavoro correlato
P28: Rischio Strategico | Q28: Comunicazione e relazioni istituzionali | R28: N.A. | S28: STR | Z28: Rischio da videoterminale
P29: Rischio Strategico | Q29: Governance | R29: N.A. | S29: STR
P30: Rischio Strategico | Q30: Immagine/Reputazione | R30: N.A. | S30: STR
P31: Rischio Strategico | Q31: Investimenti e patrimonio | R31: N.A. | S31: STR
P32: Rischio Strategico | Q32: Pianificazione strategica | R32: N.A. | S32: STR
P33: Rischio Strategico | Q33: Sistema di Controllo Interno | R33: N.A. | S33: STR
P34: Rischio Operativo | Q34: Attività, processi e procedure | R34: N.A. | S34: OPE
P35: Rischio Operativo | Q35: Asset infrastrutturali e tecnologia | R35: N.A. | S35: OPE
P36: Rischio Operativo | Q36: Business Continuity | R36: N.A. | S36: OPE
P37: Rischio Operativo | Q37: Comunicazione e relazioni | R37: N.A. | S37: OPE
P38: Rischio Operativo | Q38: Continuità e coordinamento percorsi assistenziali | R38: N.A. | S38: OPE
P39: Rischio Operativo | Q39: Edifici e spazi comuni | R39: N.A. | S39: OPE
P40: Rischio Operativo | Q40: Gestione apparecchiature sanitarie | R40: N.A. | S40: OPE
... P68: Rischio Operativo | Q68: Salute sicurezza e ambiente | R68: Rischio da videoterminale | S68: OPE
